#VRML_SIM R2025a utf8

EXTERNPROTO "https://raw.githubusercontent.com/cyberbotics/webots/R2025a/projects/objects/backgrounds/protos/TexturedBackground.proto"
EXTERNPROTO "https://raw.githubusercontent.com/cyberbotics/webots/R2025a/projects/objects/backgrounds/protos/TexturedBackgroundLight.proto"
EXTERNPROTO "https://raw.githubusercontent.com/cyberbotics/webots/R2025a/projects/objects/floors/protos/RectangleArena.proto"

WorldInfo {
}
Viewpoint {
  orientation 0.12020852692134311 -0.0989262881461212 -0.9878074202844557 3.6890716669108246
  position 0.5685511546732903 -0.11633273121353746 0.36350137856624726
}
TexturedBackground {
}
TexturedBackgroundLight {
}
RectangleArena {
  translation 0.014994 0.0593776 0
  floorTileSize 0.25 0.25
  wallHeight 0.05
}
Robot {
  translation -0.0009947883508432435 0.09786726167749825 0.037311247391584965
  rotation -0.1216352572207032 0.3610914268991047 0.9245635973911268 0.005201854274695627
  children [
    Group {
      children [
        HingeJoint {
          jointParameters HingeJointParameters {
            position 0.0019112743112266624
            axis 0 0 1
            anchor 0.0375 0.0375 0.0375
          }
          device [
            RotationalMotor {
              name "hip_motor"
              maxVelocity 6
              maxPosition 3.14
              maxTorque 1.176
            }
          ]
          endPoint Solid {
            translation 0.0624999042625388 0.037573981780835854 0.0374991
            rotation 8.904740145315264e-05 4.777327612477361e-05 0.9999999948941373 0.0019112749203182595
            children [
              HingeJoint {
                jointParameters HingeJointParameters {
                  position 0.00040869178565511354
                  axis 0 1 0
                  anchor 0.025 0 0
                }
                device [
                  RotationalMotor {
                    name "knee_motor"
                    maxVelocity 6
                    maxPosition 3.14
                    maxTorque 1.176
                  }
                ]
                endPoint Solid {
                  translation 0.049999800396383014 -0.00014054016549643045 -1.0217213633876103e-05
                  rotation -0.00020221949212995298 0.1438870460795745 -0.9895940971316328 0.002840363518650078
                  children [
                    HingeJoint {
                      jointParameters HingeJointParameters {
                        position 0.0019113517727245347
                        axis 0 1 0
                        anchor 0.025 0 0
                      }
                      device [
                        RotationalMotor {
                          name "ankle_motor"
                          maxVelocity 6
                          maxPosition 3.14
                          maxTorque 1.176
                        }
                      ]
                      endPoint Solid {
                        translation 0.04999975681878338 -0.0001405401654964304 -4.778338770174689e-05
                        rotation -0.0007902734072008841 0.5623103142795114 -0.8269259252936862 0.0033991027118271985
                        children [
                          DEF knee Shape {
                            appearance PBRAppearance {
                            }
                            geometry Box {
                              size 0.05 0.02 0.02
                            }
                          }
                        ]
                        boundingObject USE knee
                        physics Physics {
                        }
                        linearVelocity -0.0005672539858031358 -5.060719573245582e-08 0.0011645443781841919
                        angularVelocity 8.953024049677108e-05 -0.028009408903089072 1.7609594153923537e-05
                      }
                    }
                    DEF knee Shape {
                      appearance PBRAppearance {
                      }
                      geometry Box {
                        size 0.05 0.02 0.02
                      }
                    }
                  ]
                  boundingObject USE knee
                  physics Physics {
                  }
                  linearVelocity 7.338575285327845e-06 1.4730401526316461e-06 -1.4966024646501098e-05
                  angularVelocity -2.0433882616672012e-05 9.841145004311172e-05 -7.1746967135994e-07
                }
              }
              DEF hip Shape {
                appearance PBRAppearance {
                }
                geometry Box {
                  size 0.05 0.02 0.02
                }
              }
            ]
            boundingObject USE hip
            physics Physics {
            }
            linearVelocity 7.3576492710805e-06 1.5111280964075246e-06 -1.0025940187796679e-05
            angularVelocity -2.04338858056667e-05 9.841039231669694e-05 -7.174694321628419e-07
          }
        }
      ]
    }
    DEF body Shape {
      appearance PBRAppearance {
      }
      geometry Box {
        size 0.075 0.075 0.075
      }
    }
  ]
  boundingObject USE body
  physics Physics {
  }
  controller "my_controller"
  linearVelocity 3.689886273787713e-06 7.66188594310174e-07 -3.096208413505034e-06
  angularVelocity -2.0432541745838453e-05 9.840683795365844e-05 -9.027082905045911e-09
}
